Workbook

Sheet MNSKU对应品线表
A1: 店铺 | B1: 核算店铺 | C1: SKU+核算店铺 | D1: MSKU | E1: 产品编码 | F1: 产品名称 | G1: 运营 | H1: 品线 | I1: 是否淘汰款 | J1: 上架时间 | K1: 开售时间 | L1: 46053 | M1: 新老品/界定 | N1: 备注
A2: Qinkell-US | B2: Qinkell美国站 | C2: =B2&D2 | D2: 1005BG QC1 | E2: 211F1005BG4 | F2: 1005二功能落地浴缸龙头拉丝钛金 | G2: 刘皓 | H2: 落地浴缸 | I2: 是 | J2: 44494 | K2: 44494 | L2: =DATEDIF(J2,$L$1,"M") | M2: =IF(L2<18,"新品期",IF(L2<=36,"老品期","衰退期"))
A3: Qinkell-CA | B3: Qinkell加拿大站 | C3: =B3&D3 | D3: 1005BG QC1 | E3: 211F1005BG4 | F3: 1005二功能落地浴缸龙头拉丝钛金 | G3: 刘皓 | H3: 落地浴缸 | I3: 是 | J3: 44494 | K3: 44494 | L3: =DATEDIF(J3,$L$1,"M") | M3: =IF(L3<18,"新品期",IF(L3<=36,"老品期","衰退期"))
A4: Qinkell-US | B4: Qinkell美国站 | C4: =B4&D4 | D4: 1005BK QC1 | E4: 211F1005BK2 | F4: 1005二功能落地浴缸龙头酸铜发黑 | G4: 刘皓 | H4: 落地浴缸 | I4: 是 | J4: 44494 | K4: 44494 | L4: =DATEDIF(J4,$L$1,"M") | M4: =IF(L4<18,"新品期",IF(L4<=36,"老品期","衰退期"))
A5: Qinkell-CA | B5: Qinkell加拿大站 | C5: =B5&D5 | D5: 1005BK QC1 | E5: 211F1005BK2 | F5: 1005二功能落地浴缸龙头酸铜发黑 | G5: 刘皓 | H5: 落地浴缸 | I5: 是 | J5: 44494 | K5: 44494 | L5: =DATEDIF(J5,$L$1,"M") | M5: =IF(L5<18,"新品期",IF(L5<=36,"老品期","衰退期"))
A6: Qinkell-US | B6: Qinkell美国站 | C6: =B6&D6 | D6: 1005BN QC1 | E6: 211F1005BN3 | F6: 1005二功能落地浴缸龙头拉丝PVD | G6: 刘皓 | H6: 落地浴缸 | I6: 是 | J6: 44494 | K6: 44494 | L6: =DATEDIF(J6,$L$1,"M") | M6: =IF(L6<18,"新品期",IF(L6<=36,"老品期","衰退期"))
A7: Qinkell-US | B7: Qinkell美国站 | C7: =B7&D7 | D7: 1005CP QC1 | E7: 211F1005CP1 | F7: 1005二功能落地浴缸龙头铬 | G7: 刘皓 | H7: 落地浴缸 | I7: 是 | J7: 44494 | K7: 44494 | L7: =DATEDIF(J7,$L$1,"M") | M7: =IF(L7<18,"新品期",IF(L7<=36,"老品期","衰退期"))
A8: Qinkell-US | B8: Qinkell美国站 | C8: =B8&D8 | D8: 1005ORB QC1 | E8: 211F1005OB1 | F8: 1005二功能落地浴缸龙头拉丝古铜色 | G8: 刘皓 | H8: 落地浴缸 | I8: 是 | J8: 44494 | K8: 44494 | L8: =DATEDIF(J8,$L$1,"M") | M8: =IF(L8<18,"新品期",IF(L8<=36,"老品期","衰退期"))
A9: Qinkell-CA | B9: Qinkell加拿大站 | C9: =B9&D9 | D9: 1005ORB QC1 | E9: 211F1005OB1 | F9: 1005二功能落地浴缸龙头拉丝古铜色 | G9: 刘皓 | H9: 落地浴缸 | I9: 是 | J9: 44494 | K9: 44494 | L9: =DATEDIF(J9,$L$1,"M") | M9: =IF(L9<18,"新品期",IF(L9<=36,"老品期","衰退期"))
A10: Qinkell-US | B10: Qinkell美国站 | C10: =B10&D10 | D10: 1006BG QC1 | E10: 211F1006BG1 | F10: 1006二功能落地浴缸龙头拉丝钛金封油 | G10: 刘皓 | H10: 落地浴缸 | I10: 是 | J10: 44494 | K10: 44494 | L10: =DATEDIF(J10,$L$1,"M") | M10: =IF(L10<18,"新品期",IF(L10<=36,"老品期","衰退期"))
A11: Qinkell-CA | B11: Qinkell加拿大站 | C11: =B11&D11 | D11: 1006BG QC1 | E11: 211F1006BG1 | F11: 1006二功能落地浴缸龙头拉丝钛金封油 | G11: 刘皓 | H11: 落地浴缸 | I11: 是 | J11: 44494 | K11: 44494 | L11: =DATEDIF(J11,$L$1,"M") | M11: =IF(L11<18,"新品期",IF(L11<=36,"老品期","衰退期"))
A12: Qinkell-US | B12: Qinkell美国站 | C12: =B12&D12 | D12: 1006BK QC1 | E12: 211F1006BK1 | F12: 1006二功能落地浴缸龙头酸铜发黑 | G12: 刘皓 | H12: 落地浴缸 | I12: 是 | J12: 44494 | K12: 44494 | L12: =DATEDIF(J12,$L$1,"M") | M12: =IF(L12<18,"新品期",IF(L12<=36,"老品期","衰退期"))
A13: Qinkell-CA | B13: Qinkell加拿大站 | C13: =B13&D13 | D13: 1006BK QC1 | E13: 211F1006BK1 | F13: 1006二功能落地浴缸龙头酸铜发黑 | G13: 刘皓 | H13: 落地浴缸 | I13: 是 | J13: 44494 | K13: 44494 | L13: =DATEDIF(J13,$L$1,"M") | M13: =IF(L13<18,"新品期",IF(L13<=36,"老品期","衰退期"))
... A116: Qinkell-US | B116: Qinkell美国站 | C116: =B116&D116 | D116: 5002ORB QC1 | E116: 231F5002OB1 | F116: 5002二功能入墙浴缸龙头拉丝古铜色 | G116: 朱艺璇 | H116: 缸边浴缸 | I116: 是 | J116: 44409 | K116: 44409 | L116: =DATEDIF(J116,$L$1,"M") | M116: =IF(L116<18,"新品期",IF(L116<=36,"老品期","衰退期"))
A117: Jabbol-US | B117: Jabbol美国站 | C117: =B117&D117 | D117: 8801 BK-ZZ | E117: 110F0088BK1 | F117: 88系列矮身单孔正开面盆龙头电泳黑 | G117: 曾志发 | H117: 面盆 | I117: 是 | J117: 45599 | K117: 45599 | L117: =DATEDIF(J117,$L$1,"M") | M117: =IF(L117<18,"新品期",IF(L117<=36,"老品期","衰退期")) | N117: 种子链接，2025年9月1号以前梁丽梅负责
A118: Jabbol-US | B118: Jabbol美国站 | C118: =B118&D118 | D118: 8801 ORB-ZZ | E118: 110F0088OB1 | F118: 88系列矮身单孔正开面盆龙头拉丝红古铜 | G118: 曾志发 | H118: 面盆 | I118: 是 | J118: 45599 | K118: 45599 | L118: =DATEDIF(J118,$L$1,"M") | M118: =IF(L118<18,"新品期",IF(L118<=36,"老品期","衰退期")) | N118: 种子链接，2025年9月1号以前梁丽梅负责
A119: Jabbol-US | B119: Jabbol美国站 | C119: =B119&D119 | D119: 8801BGJB-1 | E119: 110F0088BG1 | F119: 88系列矮身单孔正开面盆龙头拉丝钛金封油 | G119: 曾志发 | H119: 面盆 | I119: 否 | J119: 45562 | K119: 45562 | L119: =DATEDIF(J119,$L$1,"M") | M119: =IF(L119<18,"新品期",IF(L119<=36,"老品期","衰退期")) | N119: 2025年9月1号以前梁丽梅负责
A120: Jabbol-US | B120: Jabbol美国站 | C120: =B120&D120 | D120: 8801BKJB-1 | E120: 110F0088BK1 | F120: 88系列矮身单孔正开面盆龙头电泳黑 | G120: 曾志发 | H120: 面盆 | I120: 否 | J120: 45562 | K120: 45562 | L120: =DATEDIF(J120,$L$1,"M") | M120: =IF(L120<18,"新品期",IF(L120<=36,"老品期","衰退期")) | N120: 2025年9月1号以前梁丽梅负责
A121: Jabbol-US | B121: Jabbol美国站 | C121: =B121&D121 | D121: 8801BNJB-1 | E121: 110F0088BN1 | F121: 88系列矮身单孔正开面盆龙头拉丝封油 | G121: 曾志发 | H121: 面盆 | I121: 否 | J121: 45562 | K121: 45562 | L121: =DATEDIF(J121,$L$1,"M") | M121: =IF(L121<18,"新品期",IF(L121<=36,"老品期","衰退期")) | N121: 2025年9月1号以前梁丽梅负责
A122: Jabbol-US | B122: Jabbol美国站 | C122: =B122&D122 | D122: 8801CPJB-1 | E122: 110F0088CP1 | F122: 88系列矮身单孔正开面盆龙头铬色 | G122: 曾志发 | H122: 面盆 | I122: 否 | J122: 45562 | K122: 45562 | L122: =DATEDIF(J122,$L$1,"M") | M122: =IF(L122<18,"新品期",IF(L122<=36,"老品期","衰退期")) | N122: 2025年9月1号以前梁丽梅负责
A123: Jabbol-US | B123: Jabbol美国站 | C123: =B123&D123 | D123: 8801ORBJB-1 | E123: 110F0088OB1 | F123: 88系列矮身单孔正开面盆龙头拉丝红古铜 | G123: 曾志发 | H123: 面盆 | I123: 否 | J123: 45562 | K123: 45562 | L123: =DATEDIF(J123,$L$1,"M") | M123: =IF(L123<18,"新品期",IF(L123<=36,"老品期","衰退期")) | N123: 2025年9月1号以前梁丽梅负责
A124: Jabbol-US | B124: Jabbol美国站 | C124: =B124&D124 | D124: 8804BGJB-1 | E124: 140F0088BG1 | F124: 88系列分体面盆龙头拉丝钛金封油 | G124: 曾志发 | H124: 面盆 | I124: 否 | J124: 45610 | K124: 45610 | L124: =DATEDIF(J124,$L$1,"M") | M124: =IF(L124<18,"新品期",IF(L124<=36,"老品期","衰退期")) | N124: 2025年9月1号以前梁丽梅负责
A125: Jabbol-US | B125: Jabbol美国站 | C125: =B125&D125 | D125: 8804BKJB-1 | E125: 140F0088BK1 | F125: 88系列分体面盆龙头电泳黑 | G125: 曾志发 | H125: 面盆 | I125: 否 | J125: 45610 | K125: 45610 | L125: =DATEDIF(J125,$L$1,"M") | M125: =IF(L125<18,"新品期",IF(L125<=36,"老品期","衰退期")) | N125: 2025年9月1号以前梁丽梅负责
A126: Jabbol-US | B126: Jabbol美国站 | C126: =B126&D126 | D126: 8804BNJB-1 | E126: 140F0088BN1 | F126: 88系列分体面盆龙头拉丝封油 | G126: 曾志发 | H126: 面盆 | I126: 否 | J126: 45610 | K126: 45610 | L126: =DATEDIF(J126,$L$1,"M") | M126: =IF(L126<18,"新品期",IF(L126<=36,"老品期","衰退期")) | N126: 2025年9月1号以前梁丽梅负责
A127: Jabbol-US | B127: Jabbol美国站 | C127: =B127&D127 | D127: 8804CPJB-1 | E127: 140F0088CP1 | F127: 88系列分体面盆龙头铬色 | G127: 曾志发 | H127: 面盆 | I127: 否 | J127: 45610 | K127: 45610 | L127: =DATEDIF(J127,$L$1,"M") | M127: =IF(L127<18,"新品期",IF(L127<=36,"老品期","衰退期")) | N127: 2025年9月1号以前梁丽梅负责
A128: Jabbol-US | B128: Jabbol美国站 | C128: =B128&D128 | D128: 8804ORBJB-1 | E128: 140F0088OB1 | F128: 88系列分体面盆龙头拉丝红古铜 | G128: 曾志发 | H128: 面盆 | I128: 否 | J128: 45610 | K128: 45610 | L128: =DATEDIF(J128,$L$1,"M") | M128: =IF(L128<18,"新品期",IF(L128<=36,"老品期","衰退期")) | N128: 2025年9月1号以前梁丽梅负责
A129: Jabbol-US | B129: Jabbol美国站 | C129: =B129&D129 | D129: 8807BGJB-2 | E129: 221F0088BG1 | F129: 88系列三件套缸边浴缸龙头拉丝钛金封油 | G129: 朱艺璇 | H129: 缸边浴缸 | I129: 否 | J129: 45488 | K129: 45659 | L129: =DATEDIF(J129,$L$1,"M") | M129: =IF(L129<18,"新品期",IF(L129<=36,"老品期","衰退期"))
A130: Jabbol-US | B130: Jabbol美国站 | C130: =B130&D130 | D130: 8807BGJB-ZZ | E130: 221F0088BG1 | F130: 88系列三件套缸边浴缸龙头拉丝钛金封油 | G130: 朱艺璇 | H130: 缸边浴缸 | I130: 是 | J130: 45488 | K130: 45659 | L130: =DATEDIF(J130,$L$1,"M") | M130: =IF(L130<18,"新品期",IF(L130<=36,"老品期","衰退期"))
A131: Jabbol-US | B131: Jabbol美国站 | C131: =B131&D131 | D131: 8807BK JB-ZZ01 | E131: 221F0088BK1 | F131: 88系列三件套缸边浴缸龙头电泳黑 | G131: 朱艺璇 | H131: 缸边浴缸 | I131: 是 | J131: 45488 | K131: 45659 | L131: =DATEDIF(J131,$L$1,"M") | M131: =IF(L131<18,"新品期",IF(L131<=36,"老品期","衰退期"))
A132: Jabbol-US | B132: Jabbol美国站 | C132: =B132&D132 | D132: 8807BKJB-2 | E132: 221F0088BK1 | F132: 88系列三件套缸边浴缸龙头电泳黑 | G132: 朱艺璇 | H132: 缸边浴缸 | I132: 否 | J132: 45488 | K132: 45659 | L132: =DATEDIF(J132,$L$1,"M") | M132: =IF(L132<18,"新品期",IF(L132<=36,"老品期","衰退期"))
A133: Jabbol-US | B133: Jabbol美国站 | C133: =B133&D133 | D133: 8807BKJB-ZZ | E133: 221F0088BK1 | F133: 88系列三件套缸边浴缸龙头电泳黑 | G133: 朱艺璇 | H133: 缸边浴缸 | I133: 是 | J133: 45488 | K133: 45659 | L133: =DATEDIF(J133,$L$1,"M") | M133: =IF(L133<18,"新品期",IF(L133<=36,"老品期","衰退期"))
A134: Jabbol-US | B134: Jabbol美国站 | C134: =B134&D134 | D134: 8807BN JB-ZZ01 | E134: 221F0088BN1 | F134: 88系列三件套缸边浴缸龙头拉丝封油 | G134: 朱艺璇 | H134: 缸边浴缸 | I134: 是 | J134: 45488 | K134: 45659 | L134: =DATEDIF(J134,$L$1,"M") | M134: =IF(L134<18,"新品期",IF(L134<=36,"老品期","衰退期"))
A135: Jabbol-US | B135: Jabbol美国站 | C135: =B135&D135 | D135: 8807BNJB-2 | E135: 221F0088BN1 | F135: 88系列三件套缸边浴缸龙头拉丝封油 | G135: 朱艺璇 | H135: 缸边浴缸 | I135: 否 | J135: 45488 | K135: 45659 | L135: =DATEDIF(J135,$L$1,"M") | M135: =IF(L135<18,"新品期",IF(L135<=36,"老品期","衰退期"))
A136: Jabbol-US | B136: Jabbol美国站 | C136: =B136&D136 | D136: 8807BNJB-ZZ | E136: 221F0088BN1 | F136: 88系列三件套缸边浴缸龙头拉丝封油 | G136: 朱艺璇 | H136: 缸边浴缸 | I136: 是 | J136: 45488 | K136: 45659 | L136: =DATEDIF(J136,$L$1,"M") | M136: =IF(L136<18,"新品期",IF(L136<=36,"老品期","衰退期"))
A137: Jabbol-US | B137: Jabbol美国站 | C137: =B137&D137 | D137: 8807CP JB-ZZ01 | E137: 221F0088CP1 | F137: 88系列三件套缸边浴缸龙头铬色 | G137: 朱艺璇 | H137: 缸边浴缸 | I137: 是 | J137: 45488 | K137: 45659 | L137: =DATEDIF(J137,$L$1,"M") | M137: =IF(L137<18,"新品期",IF(L137<=36,"老品期","衰退期"))
A138: Jabbol-US | B138: Jabbol美国站 | C138: =B138&D138 | D138: 8807CPJB-2 | E138: 221F0088CP1 | F138: 88系列三件套缸边浴缸龙头铬色 | G138: 朱艺璇 | H138: 缸边浴缸 | I138: 否 | J138: 45488 | K138: 45659 | L138: =DATEDIF(J138,$L$1,"M") | M138: =IF(L138<18,"新品期",IF(L138<=36,"老品期","衰退期"))
A139: Jabbol-US | B139: Jabbol美国站 | C139: =B139&D139 | D139: 8807ORBJB-2 | E139: 221F0088OB1 | F139: 88系列三件套缸边浴缸龙头拉丝红古铜 | G139: 朱艺璇 | H139: 缸边浴缸 | I139: 否 | J139: 45488 | K139: 45659 | L139: =DATEDIF(J139,$L$1,"M") | M139: =IF(L139<18,"新品期",IF(L139<=36,"老品期","衰退期"))
A140: Jabbol-US | B140: Jabbol美国站 | C140: =B140&D140 | D140: 8807ORBJB-ZZ | E140: 221F0088OB1 | F140: 88系列三件套缸边浴缸龙头拉丝红古铜 | G140: 朱艺璇 | H140: 缸边浴缸 | I140: 是 | J140: 45488 | K140: 45659 | L140: =DATEDIF(J140,$L$1,"M") | M140: =IF(L140<18,"新品期",IF(L140<=36,"老品期","衰退期"))
... A150: Jabbol-US | B150: Jabbol美国站 | C150: =B150&D150 | D150: 8809ORB JB-1 | E150: 223F0088OB1 | F150: 88系列五件套缸边浴缸龙头拉丝红古铜 | G150: 朱艺璇 | H150: 缸边浴缸 | I150: 是 | J150: 45488 | K150: 45705 | L150: =DATEDIF(J150,$L$1,"M") | M150: =IF(L150<18,"新品期",IF(L150<=36,"老品期","衰退期"))
A151: Jabbol-US | B151: Jabbol美国站 | C151: =B151&D151 | D151: 8811 BG01 | E151: 211F0088BG1 | F151: 8811落地浴缸龙头拉丝钛金封油 | G151: 刘皓 | H151: 落地浴缸 | I151: 否 | J151: 45553 | K151: 45748 | L151: =DATEDIF(J151,$L$1,"M") | M151: =IF(L151<18,"新品期",IF(L151<=36,"老品期","衰退期")) | N151: 2026年4月17日之前王幸负责
...
